Workbook
Name \a: #N/A
Name \c: #N/A
Name \d: #REF!
Name \f: #REF!
Name \q: #N/A
Name \r: #N/A
Name \s: #N/A
Name A: #REF!
Name b: #REF!
Name code1: #REF!
Name code2: #REF!
Name d: #REF!
Name ddd: #REF!
Name df: #REF!
Name ee: [2]일위대가!#REF!
Name k: #N/A
Name PRINT_AREA_MI: #N/A
Name PRINT_TITLES_MI: #REF!
Name q: #REF!
Name rlr: #REF!
Name s: #N/A
Name w: #REF!
Name x: #REF!
Name XX: #REF!
Name 공사명: '[3]내역서-토목'!#REF!
Name 기: #N/A
Name 내: #N/A
Name 내선전공: #REF!
Name 내역1: #REF!
Name 내역2: #REF!
Name 낵역4: #REF!
Name 노임: [4]노임단가!$B$1:$C$131
Name 단가: #REF!
Name 단가다: #REF!
Name 단가비교표2: #REF!
Name 단가임: #REF!
Name ㅁㅁㅁ: #REF!
Name 모니터: #REF!
Name 밧데리: #REF!
Name 보통인부: #REF!
Name 소방일위대가: [5]노무비!$B$5
Name 운반산출: #REF!
Name 원가계산: #REF!
Name 일위대가: [5]노무비!$B$2
Name 정류기: #REF!
Name 제경비율: #REF!
Name 지주: #N/A
Name 프랜트전공: #REF!
Name 프린터: #REF!
Name ㅗ호: #N/A

Sheet 공종별집계표
A1: 공 종 별 집 계 표
A2: [ 한국정보통신공사협회 제주특별자치도 회관 신축공사 ]
A3: 품 명 | B3: 규 격 | C3: 단위 | D3: 수량 | E3: 재 료 비 | G3: 노 무 비 | I3: 경 비 | K3: 합 계 | M3: 비 고 | N3: 공종코드 | O3: 변수 | P3: 상위공종 | Q3: 공종구분 | R3: 공종레벨 | S3: 공종소계 | T3: 원가계산서 연결금액
E4: 단 가 | F4: 금 액 | G4: 단 가 | H4: 금 액 | I4: 단 가 | J4: 금 액 | K4: 단 가 | L4: 금 액
A5: 01 한국정보통신공사협회 제주특별자치도 회관 신축공사 | D5: 1 | E5: =F6+F35+F41 -> 871751659 | F5: =E5*D5 -> 871751659 | G5: =H6+H35+H41 -> 364781324 | H5: =G5*D5 -> 364781324 | I5: =J6+J35+J41 -> 41583379 | J5: =I5*D5 -> 41583379 | K5: =E5+G5+I5 -> 1278116362 | L5: =F5+H5+J5 -> 1278116362 | N5: 01 | R5: 1
A6: 0101 ▼ 건축공사 ▼ | D6: 1 | E6: =F7+F8+F9+F10+F11+F12+F13+F14+F15+F16+F17+F18+F19+F20+F21+F22+F23+F24+F25+F26+F27+F28+F29+F30 -> 692729132 | F6: =E6*D6 -> 692729132 | G6: =H7+H8+H9+H10+H11+H12+H13+H14+H15+H16+H17+H18+H19+H20+H21+H22+H23+H24+H25+H26+H27+H28+H29+H30 -> 338029381 | H6: =G6*D6 -> 338029381 | I6: =J7+J8+J9+J10+J11+J12+J13+J14+J15+J16+J17+J18+J19+J20+J21+J22+J23+J24+J25+J26+J27+J28+J29+J30 -> 37131789 | J6: =I6*D6 -> 37131789 | K6: =E6+G6+I6 -> 1067890302 | L6: =F6+H6+J6 -> 1067890302 | N6: 0101 | P6: 01 | R6: 2
A7: 010101 공통 가설 공사 | D7: 1 | E7: =[1]공종별내역서!F27 -> 0 | F7: =E7*D7 -> 0 | G7: =[1]공종별내역서!H27 -> 0 | H7: =G7*D7 -> 0 | I7: =[1]공종별내역서!J27 -> 10169428 | J7: =I7*D7 -> 10169428 | K7: =E7+G7+I7 -> 10169428 | L7: =F7+H7+J7 -> 10169428 | N7: 010101 | P7: 0101 | R7: 3
A8: 010102 가 설 공 사 | D8: 1 | E8: =[1]공종별내역서!F50 -> 19382175 | F8: =E8*D8 -> 19382175 | G8: =[1]공종별내역서!H50 -> 32954542 | H8: =G8*D8 -> 32954542 | I8: =[1]공종별내역서!J50 -> 308544 | J8: =I8*D8 -> 308544 | K8: =E8+G8+I8 -> 52645261 | L8: =F8+H8+J8 -> 52645261 | N8: 010102 | P8: 0101 | R8: 3
A9: 010103 토 및 지정공사 | D9: 1 | E9: =[1]공종별내역서!F73 -> 2043376 | F9: =E9*D9 -> 2043376 | G9: =[1]공종별내역서!H73 -> 1765806 | H9: =G9*D9 -> 1765806 | I9: =[1]공종별내역서!J73 -> 1622277 | J9: =I9*D9 -> 1622277 | K9: =E9+G9+I9 -> 5431459 | L9: =F9+H9+J9 -> 5431459 | N9: 010103 | P9: 0101 | R9: 3
A10: 010104 철근콘크리트공사 | D10: 1 | E10: =[1]공종별내역서!F119 -> 262335976 | F10: =E10*D10 -> 262335976 | G10: =[1]공종별내역서!H119 -> 127543473 | H10: =G10*D10 -> 127543473 | I10: =[1]공종별내역서!J119 -> 8225750 | J10: =I10*D10 -> 8225750 | K10: =E10+G10+I10 -> 398105199 | L10: =F10+H10+J10 -> 398105199 | N10: 010104 | P10: 0101 | R10: 3
A11: 010105 조 적 공 사 | D11: 1 | E11: =[1]공종별내역서!F142 -> 954396 | F11: =E11*D11 -> 954396 | G11: =[1]공종별내역서!H142 -> 2252996 | H11: =G11*D11 -> 2252996 | I11: =[1]공종별내역서!J142 -> 35479 | J11: =I11*D11 -> 35479 | K11: =E11+G11+I11 -> 3242871 | L11: =F11+H11+J11 -> 3242871 | N11: 010105 | P11: 0101 | R11: 3
A12: 010106 돌 공 사 | D12: 1 | E12: =[1]공종별내역서!F165 -> 78691117 | F12: =E12*D12 -> 78691117 | G12: =[1]공종별내역서!H165 -> 65862468 | H12: =G12*D12 -> 65862468 | I12: =[1]공종별내역서!J165 -> 1879689 | J12: =I12*D12 -> 1879689 | K12: =E12+G12+I12 -> 146433274 | L12: =F12+H12+J12 -> 146433274 | N12: 010106 | P12: 0101 | R12: 3
A13: 010107 타 일 공 사 | D13: 1 | E13: =[1]공종별내역서!F188 -> 19581641 | F13: =E13*D13 -> 19581641 | G13: =[1]공종별내역서!H188 -> 18144801 | H13: =G13*D13 -> 18144801 | I13: =[1]공종별내역서!J188 -> 451520 | J13: =I13*D13 -> 451520 | K13: =E13+G13+I13 -> 38177962 | L13: =F13+H13+J13 -> 38177962 | N13: 010107 | P13: 0101 | R13: 3
A14: 010108 목공사및수장공사 | D14: 1 | E14: =[1]공종별내역서!F211 -> 70662143 | F14: =E14*D14 -> 70662143 | G14: =[1]공종별내역서!H211 -> 17135253 | H14: =G14*D14 -> 17135253 | I14: =[1]공종별내역서!J211 -> 275654 | J14: =I14*D14 -> 275654 | K14: =E14+G14+I14 -> 88073050 | L14: =F14+H14+J14 -> 88073050 | N14: 010108 | P14: 0101 | R14: 3
A15: 010109 방 수 공 사 | D15: 1 | E15: =[1]공종별내역서!F234 -> 13982936 | F15: =E15*D15 -> 13982936 | G15: =[1]공종별내역서!H234 -> 14490124 | H15: =G15*D15 -> 14490124 | I15: =[1]공종별내역서!J234 -> 358652 | J15: =I15*D15 -> 358652 | K15: =E15+G15+I15 -> 28831712 | L15: =F15+H15+J15 -> 28831712 | N15: 010109 | P15: 0101 | R15: 3
A16: 010110 지붕 및 홈통공사 | D16: 1 | E16: =[1]공종별내역서!F257 -> 3390559 | F16: =E16*D16 -> 3390559 | G16: =[1]공종별내역서!H257 -> 3098404 | H16: =G16*D16 -> 3098404 | I16: =[1]공종별내역서!J257 -> 0 | J16: =I16*D16 -> 0 | K16: =E16+G16+I16 -> 6488963 | L16: =F16+H16+J16 -> 6488963 | N16: 010110 | P16: 0101 | R16: 3
A17: 010111 금 속 공 사 | D17: 1 | E17: =[1]공종별내역서!F280 -> 48238363 | F17: =E17*D17 -> 48238363 | G17: =[1]공종별내역서!H280 -> 17694863 | H17: =G17*D17 -> 17694863 | I17: =[1]공종별내역서!J280 -> 612555 | J17: =I17*D17 -> 612555 | K17: =E17+G17+I17 -> 66545781 | L17: =F17+H17+J17 -> 66545781 | N17: 010111 | P17: 0101 | R17: 3
A18: 010112 미 장 공 사 | D18: 1 | E18: =[1]공종별내역서!F303 -> 3135430 | F18: =E18*D18 -> 3135430 | G18: =[1]공종별내역서!H303 -> 15926409 | H18: =G18*D18 -> 15926409 | I18: =[1]공종별내역서!J303 -> 273426 | J18: =I18*D18 -> 273426 | K18: =E18+G18+I18 -> 19335265 | L18: =F18+H18+J18 -> 19335265 | N18: 010112 | P18: 0101 | R18: 3
A19: 010113 창 호 공 사 | D19: 1 | E19: =[1]공종별내역서!F349 -> 65449170 | F19: =E19*D19 -> 65449170 | G19: =[1]공종별내역서!H349 -> 6948573 | H19: =G19*D19 -> 6948573 | I19: =[1]공종별내역서!J349 -> 2119733 | J19: =I19*D19 -> 2119733 | K19: =E19+G19+I19 -> 74517476 | L19: =F19+H19+J19 -> 74517476 | N19: 010113 | P19: 0101 | R19: 3
A20: 010114 유 리 공 사 | D20: 1 | E20: =[1]공종별내역서!F372 -> 23959872 | F20: =E20*D20 -> 23959872 | G20: =[1]공종별내역서!H372 -> 995252 | H20: =G20*D20 -> 995252 | I20: =[1]공종별내역서!J372 -> 87305 | J20: =I20*D20 -> 87305 | K20: =E20+G20+I20 -> 25042429 | L20: =F20+H20+J20 -> 25042429 | N20: 010114 | P20: 0101 | R20: 3
A21: 010115 칠 공 사 | D21: 1 | E21: =[1]공종별내역서!F395 -> 15430839 | F21: =E21*D21 -> 15430839 | G21: =[1]공종별내역서!H395 -> 5838022 | H21: =G21*D21 -> 5838022 | I21: =[1]공종별내역서!J395 -> 0 | J21: =I21*D21 -> 0 | K21: =E21+G21+I21 -> 21268861 | L21: =F21+H21+J21 -> 21268861 | N21: 010115 | P21: 0101 | R21: 3
A22: 010116 기 타 공 사 | D22: 1 | E22: =[1]공종별내역서!F418 -> 2715920 | F22: =E22*D22 -> 2715920 | G22: =[1]공종별내역서!H418 -> 393121 | H22: =G22*D22 -> 393121 | I22: =[1]공종별내역서!J418 -> 9274 | J22: =I22*D22 -> 9274 | K22: =E22+G22+I22 -> 3118315 | L22: =F22+H22+J22 -> 3118315 | N22: 010116 | P22: 0101 | R22: 3
A23: 010117 간 판 공 사 | D23: 1 | E23: =[1]공종별내역서!F441 -> 3251630 | F23: =E23*D23 -> 3251630 | G23: =[1]공종별내역서!H441 -> 440600 | H23: =G23*D23 -> 440600 | I23: =[1]공종별내역서!J441 -> 440600 | J23: =I23*D23 -> 440600 | K23: =E23+G23+I23 -> 4132830 | L23: =F23+H23+J23 -> 4132830 | N23: 010117 | P23: 0101 | R23: 3
A24: 010118 조 경 공 사 | D24: 1 | E24: =[1]공종별내역서!F464 -> 6012534 | F24: =E24*D24 -> 6012534 | G24: =[1]공종별내역서!H464 -> 544674 | H24: =G24*D24 -> 544674 | I24: =[1]공종별내역서!J464 -> 44440 | J24: =I24*D24 -> 44440 | K24: =E24+G24+I24 -> 6601648 | L24: =F24+H24+J24 -> 6601648 | N24: 010118 | P24: 0101 | R24: 3
A25: 010119 장애인편의시설 | D25: 1 | E25: =[1]공종별내역서!F487 -> 431788 | F25: =E25*D25 -> 431788 | G25: =[1]공종별내역서!H487 -> 0 | H25: =G25*D25 -> 0 | I25: =[1]공종별내역서!J487 -> 0 | J25: =I25*D25 -> 0 | K25: =E25+G25+I25 -> 431788 | L25: =F25+H25+J25 -> 431788 | N25: 010119 | P25: 0101 | R25: 3
A26: 010120 판 넬 공 사 | D26: 1 | E26: =[1]공종별내역서!F510 -> 24424117 | F26: =E26*D26 -> 24424117 | G26: =[1]공종별내역서!H510 -> 0 | H26: =G26*D26 -> 0 | I26: =[1]공종별내역서!J510 -> 0 | J26: =I26*D26 -> 0 | K26: =E26+G26+I26 -> 24424117 | L26: =F26+H26+J26 -> 24424117 | N26: 010120 | P26: 0101 | R26: 3
A27: 010121 지반보강공사 | D27: 1 | E27: =[1]공종별내역서!F533 -> 4000000 | F27: =E27*D27 -> 4000000 | G27: =[1]공종별내역서!H533 -> 6000000 | H27: =G27*D27 -> 6000000 | I27: =[1]공종별내역서!J533 -> 10000000 | J27: =I27*D27 -> 10000000 | K27: =E27+G27+I27 -> 20000000 | L27: =F27+H27+J27 -> 20000000 | N27: 010121 | P27: 0101 | R27: 3
A28: 010122 골 재 비 | D28: 1 | E28: =[1]공종별내역서!F556 -> 11655150 | F28: =E28*D28 -> 11655150 | G28: =[1]공종별내역서!H556 -> 0 | H28: =G28*D28 -> 0 | I28: =[1]공종별내역서!J556 -> 0 | J28: =I28*D28 -> 0 | K28: =E28+G28+I28 -> 11655150 | L28: =F28+H28+J28 -> 11655150 | N28: 010122 | P28: 0101 | R28: 3
A29: 010123 철 거 공 사 | D29: 1 | E29: =[1]공종별내역서!F579 -> 13000000 | F29: =E29*D29 -> 13000000 | G29: =[1]공종별내역서!H579 -> 0 | H29: =G29*D29 -> 0 | I29: =[1]공종별내역서!J579 -> 0 | J29: =I29*D29 -> 0 | K29: =E29+G29+I29 -> 13000000 | L29: =F29+H29+J29 -> 13000000 | N29: 010123 | P29: 0101 | R29: 3
A30: 010124 건설폐기물상차비 | B30: 환경관리비 | D30: 1 | E30: =[1]공종별내역서!F602 -> 0 | F30: =E30*D30 -> 0 | G30: =[1]공종별내역서!H602 -> 0 | H30: =G30*D30 -> 0 | I30: =[1]공종별내역서!J602 -> 217463 | J30: =I30*D30 -> 217463 | K30: =E30+G30+I30 -> 217463 | L30: =F30+H30+J30 -> 217463 | N30: 010124 | P30: 0101 | R30: 3
A31: 0102 철 거 고 재 | B31: 기존건물 철거공사 | D31: 1 | E31: =[1]공종별내역서!F625 -> -500000 | F31: =E31*D31 -> -500000 | G31: =[1]공종별내역서!H625 -> 0 | H31: =G31*D31 -> 0 | I31: =[1]공종별내역서!J625 -> 0 | J31: =I31*D31 -> 0 | K31: =E31+G31+I31 -> -500000 | L31: =F31+H31+J31 -> -500000 | N31: 0102 | Q31: A | R31: 2 | T31: =L31*1 -> -500000
A32: 0103 작 업 부 산 물 | D32: 1 | E32: =[1]공종별내역서!F648 -> -672531 | F32: =E32*D32 -> -672531 | G32: =[1]공종별내역서!H648 -> 0 | H32: =G32*D32 -> 0 | I32: =[1]공종별내역서!J648 -> 0 | J32: =I32*D32 -> 0 | K32: =E32+G32+I32 -> -672531 | L32: =F32+H32+J32 -> -672531 | N32: 0103 | Q32: 1 | R32: 2 | T32: =L32*1 -> -672531
A33: 0104 품질관리비 | D33: 1 | E33: =[1]공종별내역서!F671 -> 0 | F33: =E33*D33 -> 0 | G33: =[1]공종별내역서!H671 -> 0 | H33: =G33*D33 -> 0 | I33: =[1]공종별내역서!J671 -> 1259352 | J33: =I33*D33 -> 1259352 | K33: =E33+G33+I33 -> 1259352 | L33: =F33+H33+J33 -> 1259352 | N33: 0104 | Q33: 4 | R33: 2 | T33: =L33*1 -> 1259352
A34: 0105 안전관리비 | D34: 1 | E34: =[1]공종별내역서!F694 -> 0 | F34: =E34*D34 -> 0 | G34: =[1]공종별내역서!H694 -> 0 | H34: =G34*D34 -> 0 | I34: =[1]공종별내역서!J694 -> 2731720 | J34: =I34*D34 -> 2731720 | K34: =E34+G34+I34 -> 2731720 | L34: =F34+H34+J34 -> 2731720 | N34: 0105 | Q34: 5 | R34: 2 | T34: =L34*1 -> 2731720
A35: 0106 ▼ 기계설비공사 ▼ | D35: 1 | E35: =F36+F37+F38+F39+F40 -> 130245519 | F35: =E35*D35 -> 130245519 | G35: =H36+H37+H38+H39+H40 -> 11769880 | H35: =G35*D35 -> 11769880 | I35: =J36+J37+J38+J39+J40 -> 440600 | J35: =I35*D35 -> 440600 | K35: =E35+G35+I35 -> 142455999 | L35: =F35+H35+J35 -> 142455999 | N35: 0106 | P35: 01 | R35: 2
A36: 010601 장비 및 위생기구 신설공사 | D36: 1 | E36: =[1]공종별내역서!F717 -> 24341463 | F36: =E36*D36 -> 24341463 | G36: =[1]공종별내역서!H717 -> 2215278 | H36: =G36*D36 -> 2215278 | I36: =[1]공종별내역서!J717 -> 440600 | J36: =I36*D36 -> 440600 | K36: =E36+G36+I36 -> 26997341 | L36: =F36+H36+J36 -> 26997341 | N36: 010601 | P36: 0106 | R36: 3
A37: 010602 급수, 급탕배관 신설공사 | D37: 1 | E37: =[1]공종별내역서!F809 -> 8521975 | F37: =E37*D37 -> 8521975 | G37: =[1]공종별내역서!H809 -> 4018927 | H37: =G37*D37 -> 4018927 | I37: =[1]공종별내역서!J809 -> 0 | J37: =I37*D37 -> 0 | K37: =E37+G37+I37 -> 12540902 | L37: =F37+H37+J37 -> 12540902 | N37: 010602 | P37: 0106 | R37: 3
A38: 010603 오, 배수배관 신설공사 | D38: 1 | E38: =[1]공종별내역서!F878 -> 3631914 | F38: =E38*D38 -> 3631914 | G38: =[1]공종별내역서!H878 -> 4706229 | H38: =G38*D38 -> 4706229 | I38: =[1]공종별내역서!J878 -> 0 | J38: =I38*D38 -> 0 | K38: =E38+G38+I38 -> 8338143 | L38: =F38+H38+J38 -> 8338143 | N38: 010603 | P38: 0106 | R38: 3
A39: 010604 환기배관 신설공사 | D39: 1 | E39: =[1]공종별내역서!F901 -> 464124 | F39: =E39*D39 -> 464124 | G39: =[1]공종별내역서!H901 -> 829446 | H39: =G39*D39 -> 829446 | I39: =[1]공종별내역서!J901 -> 0 | J39: =I39*D39 -> 0 | K39: =E39+G39+I39 -> 1293570 | L39: =F39+H39+J39 -> 1293570 | N39: 010604 | P39: 0106 | R39: 3
A40: 010605 냉난방기 신설공사 | D40: 1 | E40: =[1]공종별내역서!F947 -> 93286043 | F40: =E40*D40 -> 93286043 | G40: =[1]공종별내역서!H947 -> 0 | H40: =G40*D40 -> 0 | I40: =[1]공종별내역서!J947 -> 0 | J40: =I40*D40 -> 0 | K40: =E40+G40+I40 -> 93286043 | L40: =F40+H40+J40 -> 93286043 | N40: 010605 | P40: 0106 | R40: 3
...
